Workbook

Sheet Synthèse
A1: Budget interne, pas un devis. Marge commerciale non incluse.
A3: Poste | B3: Sous-total HT (€) | C3: Contingence | D3: Montant contingence (€) | E3: Total HT (€)
A4: Outil stocks | B4: =Stocks!F28 | C4: =TJM!B14 | D4: =Stocks!F30 | E4: =B4+D4
A5: Appli de commande | B5: =Commande!F50 | C5: =TJM!B15 | D5: =Commande!F52 | E5: =B5+D5
A6: Transverse | B6: =Transverse!G17 | C6: =TJM!B16 | D6: =Transverse!G18 | E6: =B6+D6
A7: Total HT | B7: =SUM(B4:B6) | D7: =SUM(D4:D6) | E7: =SUM(E4:E6)
A8: TVA 20 % | E8: =E7*TJM!B17
A9: Total TTC | E9: =E7+E8
A11: Jours-homme | B11: Outil stocks | C11: =Stocks!C28
B12: Appli de commande | C12: =Commande!C50
B13: Transverse (j.h seulement) | C13: =SUMIF(Transverse!D4:D15,"j.h",Transverse!C4:C15)
B14: Total | C14: =SUM(C11:C13)

Sheet TJM
A1: TJM retenus (€ HT par jour). Cellules bleues = valeurs saisies, à modifier ici.
A3: Rôle | B3: TJM (€) | C3: Source
A4: Chef de projet | B4: 600 | C4: Silkhom 2025 CDP confirmé grandes villes 500-650, TJMètre 2026 médian 600
A5: UX/UI | B5: 450 | C5: Silkhom 2025 UX/UI confirmé grandes villes 330-450, freelance-informatique 3-4 ans 440
A6: Dev front | B6: 450 | C6: Silkhom 2025 front JS confirmé grandes villes 350-450, haut de fourchette
A7: Dev back | B7: 450 | C7: Malt 2026 Symfony 3-7 ans 401, 8-15 ans 523
A8: Dev | B8: 450 | C8: même base que dev front / back
A9: QA | B9: 450 | C9: Silkhom 2025 testeur QA confirmé grandes villes 350-450, haut de fourchette
A10: DevOps | B10: 550 | C10: Silkhom 2025 DevOps confirmé grandes villes 450-530, TJMètre 600
A11: Consultant RGPD | B11: 700 | C11: Free-Work 665 en direct, donneespersonnelles.fr 800-1200
A13: Contingence
A14: Contingence stocks | B14: 0.08
A15: Contingence commande | B15: 0.15
A16: Contingence Transverse | B16: 0.05
A17: TVA | B17: 0.2

Sheet Stocks
A1: Outil stocks, grille de coûts par lot. Charge en jours-homme, tâche de 7 j max.
A3: Lot | B3: Tâche | C3: Charge (j.h) | D3: Rôle | E3: TJM (€) | F3: Sous-total (€ HT)
A4: Cadrage | B4: Atelier de lancement avec Picard | C4: 1 | D4: Chef de projet | E4: =TJM!$B$4 | F4: =C4*E4
A5: Cadrage | B5: Spécification courte et backlog | C5: 2 | D5: Chef de projet | E5: =TJM!$B$4 | F5: =C5*E5
A6: Cadrage | B6: Choix techniques et squelette de projet | C6: 1 | D6: Dev front | E6: =TJM!$B$6 | F6: =C6*E6
A7: UX/UI | B7: Parcours et wireframes | C7: 1 | D7: UX/UI | E7: =TJM!$B$5 | F7: =C7*E7
A8: UX/UI | B8: Maquettes des écrans (liste, fiche, formulaire, stock) | C8: 2 | D8: UX/UI | E8: =TJM!$B$5 | F8: =C8*E8
A9: Front TypeScript | B9: Interfaces et types produit | C9: 1 | D9: Dev front | E9: =TJM!$B$6 | F9: =C9*E9
A10: Front TypeScript | B10: Ajout et suppression de produit | C10: 2 | D10: Dev front | E10: =TJM!$B$6 | F10: =C10*E10
A11: Front TypeScript | B11: Gestion des quantités et de la disponibilité | C11: 2 | D11: Dev front | E11: =TJM!$B$6 | F11: =C11*E11
A12: Front TypeScript | B12: Liste, tri et filtres | C12: 2 | D12: Dev front | E12: =TJM!$B$6 | F12: =C12*E12
A13: Front TypeScript | B13: Validation des saisies | C13: 2 | D13: Dev front | E13: =TJM!$B$6 | F13: =C13*E13
A14: Front TypeScript | B14: Illustration et stockage local | C14: 1 | D14: Dev front | E14: =TJM!$B$6 | F14: =C14*E14
A15: Front TypeScript | B15: Intégration des maquettes (Bootstrap) | C15: 2 | D15: Dev front | E15: =TJM!$B$6 | F15: =C15*E15
A16: Recette | B16: Plan de test | C16: 1 | D16: QA | E16: =TJM!$B$9 | F16: =C16*E16
A17: Recette | B17: Campagne de test | C17: 2 | D17: QA | E17: =TJM!$B$9 | F17: =C17*E17
A18: Recette | B18: Corrections | C18: 2 | D18: Dev front | E18: =TJM!$B$6 | F18: =C18*E18
A19: Mise en prod | B19: Build et déploiement statique | C19: 1 | D19: DevOps | E19: =TJM!$B$10 | F19: =C19*E19
A20: Mise en prod | B20: Documentation et passation | C20: 1 | D20: Dev front | E20: =TJM!$B$6 | F20: =C20*E20
A22: Sous-totaux par lot
A23: Cadrage | C23: =SUMIF($A$4:$A$20,A23,$C$4:$C$20) | F23: =SUMIF($A$4:$A$20,A23,$F$4:$F$20)
A24: UX/UI | C24: =SUMIF($A$4:$A$20,A24,$C$4:$C$20) | F24: =SUMIF($A$4:$A$20,A24,$F$4:$F$20)
A25: Front TypeScript | C25: =SUMIF($A$4:$A$20,A25,$C$4:$C$20) | F25: =SUMIF($A$4:$A$20,A25,$F$4:$F$20)
A26: Recette | C26: =SUMIF($A$4:$A$20,A26,$C$4:$C$20) | F26: =SUMIF($A$4:$A$20,A26,$F$4:$F$20)
A27: Mise en prod | C27: =SUMIF($A$4:$A$20,A27,$C$4:$C$20) | F27: =SUMIF($A$4:$A$20,A27,$F$4:$F$20)
A28: Total avant contingence | C28: =SUM(C4:C20) | F28: =SUM(F4:F20)
A29: Contrôle sous-totaux (doit être 0) | F29: =F28-SUM(F23:F27)
A30: Contingence | E30: =TJM!$B$14 | F30: =F28*E30
A31: Total HT avec contingence | F31: =F28+F30
A32: Tâche la plus longue (j.h) | C32: =MAX(C4:C20)

Sheet Commande
A1: Appli de commande, grille de coûts par lot. Charge en jours-homme, tâche de 7 j max.
A3: Lot | B3: Tâche | C3: Charge (j.h) | D3: Rôle | E3: TJM (€) | F3: Sous-total (€ HT)
A4: Cadrage | B4: Atelier de lancement avec Picard | C4: 1 | D4: Chef de projet | E4: =TJM!$B$4 | F4: =C4*E4
A5: Cadrage | B5: Spécification fonctionnelle | C5: 3 | D5: Chef de projet | E5: =TJM!$B$4 | F5: =C5*E5
A6: Cadrage | B6: Règles de paiement et de fidélité avec Picard | C6: 1 | D6: Chef de projet | E6: =TJM!$B$4 | F6: =C6*E6
A7: Cadrage | B7: Backlog et découpage en sprints | C7: 2 | D7: Chef de projet | E7: =TJM!$B$4 | F7: =C7*E7
A8: UX/UI | B8: Parcours utilisateur (borne et téléphone) | C8: 2 | D8: UX/UI | E8: =TJM!$B$5 | F8: =C8*E8
A9: UX/UI | B9: Maquettes catalogue et commande | C9: 3 | D9: UX/UI | E9: =TJM!$B$5 | F9: =C9*E9
A10: UX/UI | B10: Maquettes paiement, compte et historique | C10: 3 | D10: UX/UI | E10: =TJM!$B$5 | F10: =C10*E10
A11: UX/UI | B11: Mini design system | C11: 1 | D11: UX/UI | E11: =TJM!$B$5 | F11: =C11*E11
A12: Back Symfony | B12: Setup projet, Docker, authentification JWT | C12: 3 | D12: Dev back | E12: =TJM!$B$7 | F12: =C12*E12
A13: Back Symfony | B13: Modèle de données et migrations | C13: 2 | D13: Dev back | E13: =TJM!$B$7 | F13: =C13*E13
A14: Back Symfony | B14: API produits | C14: 2 | D14: Dev back | E14: =TJM!$B$7 | F14: =C14*E14
A15: Back Symfony | B15: API commande et calcul du total | C15: 3 | D15: Dev back | E15: =TJM!$B$7 | F15: =C15*E15
A16: Back Symfony | B16: Validation carte côté serveur (Luhn, expiration) | C16: 1 | D16: Dev back | E16: =TJM!$B$7 | F16: =C16*E16
A17: Back Symfony | B17: API compte fidélité et points | C17: 2 | D17: Dev back | E17: =TJM!$B$7 | F17: =C17*E17
A18: Back Symfony | B18: API historique des commandes | C18: 1 | D18: Dev back | E18: =TJM!$B$7 | F18: =C18*E18
A19: Back Symfony | B19: Seeders et jeu de données | C19: 1 | D19: Dev back | E19: =TJM!$B$7 | F19: =C19*E19
A20: Back Symfony | B20: Tests automatisés | C20: 2 | D20: Dev back | E20: =TJM!$B$7 | F20: =C20*E20
A21: Back Symfony | B21: Contrat d'API (OpenAPI) et mocks | C21: 2 | D21: Dev back | E21: =TJM!$B$7 | F21: =C21*E21
A22: Front React | B22: Setup, routing, gestion d'état | C22: 2 | D22: Dev front | E22: =TJM!$B$6 | F22: =C22*E22
A23: Front React | B23: Catalogue produits | C23: 3 | D23: Dev front | E23: =TJM!$B$6 | F23: =C23*E23
A24: Front React | B24: Panier et tunnel de commande | C24: 4 | D24: Dev front | E24: =TJM!$B$6 | F24: =C24*E24
A25: Front React | B25: Formulaire de paiement et validation carte | C25: 3 | D25: Dev front | E25: =TJM!$B$6 | F25: =C25*E25
A26: Front React | B26: Inscription, connexion, compte fidélité | C26: 3 | D26: Dev front | E26: =TJM!$B$6 | F26: =C26*E26
A27: Front React | B27: Historique des commandes | C27: 2 | D27: Dev front | E27: =TJM!$B$6 | F27: =C27*E27
A28: Front React | B28: Intégration des maquettes | C28: 2 | D28: Dev front | E28: =TJM!$B$6 | F28: =C28*E28
A29: Intégration front/back | B29: Branchement des écrans, CORS, tokens | C29: 3 | D29: Dev front | E29: =TJM!$B$6 | F29: =C29*E29
A30: Intégration front/back | B30: Corrections croisées et cas limites | C30: 3 | D30: Dev back | E30: =TJM!$B$7 | F30: =C30*E30
A31: RGPD | B31: Registre, mentions, politique courte | C31: 2 | D31: Consultant RGPD | E31: =TJM!$B$11 | F31: =C31*E31
A32: RGPD | B32: Suppression de compte, consentement, durées | C32: 2 | D32: Dev back | E32: =TJM!$B$7 | F32: =C32*E32
A33: Recette | B33: Plan de test et jeux de données | C33: 2 | D33: QA | E33: =TJM!$B$9 | F33: =C33*E33
A34: Recette | B34: Campagnes de test (deux passes) | C34: 5 | D34: QA | E34: =TJM!$B$9 | F34: =C34*E34
A35: Recette | B35: Corrections | C35: 5 | D35: Dev | E35: =TJM!$B$8 | F35: =C35*E35
A36: Recette | B36: Recette utilisateur avec Picard | C36: 1 | D36: Chef de projet | E36: =TJM!$B$4 | F36: =C36*E36
A37: Déploiement | B37: Serveur, Docker, base, HTTPS | C37: 3 | D37: DevOps | E37: =TJM!$B$10 | F37: =C37*E37
A38: Déploiement | B38: CI et mise en prod | C38: 2 | D38: DevOps | E38: =TJM!$B$10 | F38: =C38*E38
A39: Déploiement | B39: Documentation technique | C39: 1 | D39: Dev back | E39: =TJM!$B$7 | F39: =C39*E39
A41: Sous-totaux par lot
A42: Cadrage | C42: =SUMIF($A$4:$A$39,A42,$C$4:$C$39) | F42: =SUMIF($A$4:$A$39,A42,$F$4:$F$39)
...

Sheet Transverse
A1: Postes transverses aux deux projets. Prix hébergement HT (OVHcloud page VPS, sept. 2026), Figma 16 $ pris à 15 €.
A3: Lot | B3: Poste | C3: Quantité | D3: Unité | E3: Rôle ou fournisseur | F3: Prix unitaire (€) | G3: Sous-total (€ HT)
A4: Pilotage | B4: Suivi hebdo outil stocks (0,5 j sur 6 semaines) | C4: 3 | D4: j.h | E4: Chef de projet | F4: =TJM!$B$4 | G4: =C4*F4
A5: Pilotage | B5: Suivi hebdo appli commande (0,5 j sur 14 semaines) | C5: 7 | D5: j.h | E5: Chef de projet | F5: =TJM!$B$4 | G5: =C5*F5
A6: Hébergement et outils | B6: VPS-2 OVHcloud, production | C6: 12 | D6: mois | E6: OVHcloud | F6: 7.21 | G6: =C6*F6
A7: Hébergement et outils | B7: VPS-1 OVHcloud, staging | C7: 12 | D7: mois | E7: OVHcloud | F7: 3.81 | G7: =C7*F7
A8: Hébergement et outils | B8: Figma Professional, 1 siège | C8: 4 | D8: mois | E8: Figma | F8: 14 | G8: =C8*F8
A9: Formation | B9: Support de formation | C9: 1 | D9: j.h | E9: Chef de projet | F9: =TJM!$B$4 | G9: =C9*F9
A10: Formation | B10: Session gestion des stocks (outil stocks) | C10: 0.5 | D10: j.h | E10: Chef de projet | F10: =TJM!$B$4 | G10: =C10*F10
A11: Formation | B11: Session commandes et fidélité (appli commande) | C11: 0.5 | D11: j.h | E11: Chef de projet | F11: =TJM!$B$4 | G11: =C11*F11
A12: Maintenance an 1 | B12: Correctifs outil stocks (0,25 j par mois) | C12: 3 | D12: j.h | E12: Dev | F12: =TJM!$B$8 | G12: =C12*F12
A13: Maintenance an 1 | B13: Correctifs appli commande, mois 1 à 6 | C13: 4.5 | D13: j.h | E13: Dev | F13: =TJM!$B$8 | G13: =C13*F13
A14: Maintenance an 1 | B14: Correctifs appli commande, mois 7 à 12 | C14: 4.5 | D14: j.h | E14: Dev | F14: =TJM!$B$8 | G14: =C14*F14
A15: Maintenance an 1 | B15: Mises à jour sécurité et dépendances | C15: 2 | D15: j.h | E15: DevOps | F15: =TJM!$B$10 | G15: =C15*F15
A17: Total avant contingence | G17: =SUM(G4:G15)
A18: Contingence | F18: =TJM!$B$16 | G18: =G17*F18
A19: Total HT avec contingence | G19: =G17+G18

Sheet Planning
A1: Planning indicatif sur 14 semaines. Une cellule colorée = le lot est actif cette semaine. J = jalon.
A3: Projet | B3: Lot | C3: S1 | D3: S2 | E3: S3 | F3: S4 | G3: S5 | H3: S6 | I3: S7 | J3: S8 | K3: S9 | L3: S10 | M3: S11 | N3: S12 | O3: S13 | P3: S14
A4: Stocks | B4: Cadrage
A5: Stocks | B5: UX/UI
A6: Stocks | B6: Front TypeScript
A7: Stocks | B7: Recette
A8: Stocks | B8: Mise en prod
A9: Commande | B9: Cadrage
A10: Commande | B10: UX/UI
A11: Commande | B11: Back Symfony (contrat d'API en tête)
A12: Commande | B12: Front React
A13: Commande | B13: Intégration front/back
A14: Commande | B14: RGPD (consultant)
A15: Commande | B15: RGPD (dev)
... A20: Transverse | B20: Formation
A22: Jalons
A23: S1 | B23: Kick-off | C23: J
A24: S2 | B24: Validation des maquettes stocks | D24: J
A25: S4 | B25: Validation des maquettes commande | F25: J
A26: S6 | B26: Mise en prod de l'outil stocks | H26: J
A27: S13 | B27: PV de recette de l'appli commande | O27: J
A28: S14 | B28: Mise en prod de l'appli commande et formation | P28: J
A30: Dépendances : UX avant front, contrat d'API avant front, back avant intégration, staging avant recette, recette avant prod.
